 <?xml version="1.0" ?>
<sdf version="1.10">
    <model name="rover">
        <link name="base_link">

        <sensor name="imu_sensor" type="imu">
            <always_on>1</always_on>
            <update_rate>100</update_rate>
            <visualize>true</visualize>
            <topic>imu</topic>
            <gz_frame_id>rover/base_link</gz_frame_id>
        </sensor>

        <inertial>
            <pose>2.04381831142401E-09 1.56408869429724E-17 -0.0015 0 0 0</pose>
            <mass>0.0757356843292425</mass>
            <inertia>
            <ixx>9.30542487791855E-05</ixx>
            <ixy>-1.72973378957802E-10</ixy>
            <ixz>-1.66079077298931E-21</ixz>
            <iyy>0.000382138338193282</iyy>
            <iyz>3.43912726365504E-23</iyz>
            <izz>0.000475078982714826</izz>
            </inertia>
        </inertial>
        <visual name="base_link_visual">
            <pose>0 0 0 0 0 0</pose>
            <geometry>
            <mesh>
                <uri>model://rover/meshes/base_link.STL</uri>
            </mesh>
            </geometry>
            <material>
            <ambient>0.792156862745098 0.819607843137255 0.933333333333333 1</ambient>
            <diffuse>0.792156862745098 0.819607843137255 0.933333333333333 1</diffuse>
            </material>
        </visual>
        <collision name="base_link_collision">
            <pose>0 0 0 0 0 0</pose>
            <geometry>
            <mesh>
                <uri>model://rover/meshes/base_link.STL</uri>
            </mesh>
            </geometry>
        </collision>
        </link>

        <link name="LD14P_Link">
        <pose relative_to="base_link">-0.00012702 0 0.03845 0 0 0</pose>
        <inertial>
            <pose>0.015195 -9.1663E-05 -0.019909 0 0 0</pose>
            <mass>0.025443</mass>
            <inertia>
            <ixx>5.3011E-06</ixx>
            <ixy>-1.5024E-08</ixy>
            <ixz>1.2999E-09</ixz>
            <iyy>8.6464E-06</iyy>
            <iyz>-1.8484E-08</iyz>
            <izz>1.3337E-05</izz>
            </inertia>
        </inertial>
        <visual name="LD14P_Link_visual">
            <pose>0 0 0 0 0 0</pose>
            <geometry>
            <mesh>
                <uri>model://rover/meshes/LD14P_Link.STL</uri>
            </mesh>
            </geometry>
            <material>
            <ambient>0.79216 0.81961 0.93333 1</ambient>
            <diffuse>0.79216 0.81961 0.93333 1</diffuse>
            </material>
        </visual>
        <collision name="LD14P_Link_collision">
            <pose>0 0 0 0 0 0</pose>
            <geometry>
            <mesh>
                <uri>model://rover/meshes/LD14P_Link.STL</uri>
            </mesh>
            </geometry>
        </collision>

        <sensor name="LD14P_lidar" type="gpu_lidar">
            <topic>scan</topic>
            <update_rate>6</update_rate>
            <ray>
                <scan>
                    <horizontal>
                        <samples>360</samples>
                        <resolution>1</resolution>
                        <min_angle>0</min_angle>
                        <max_angle>6.28319</max_angle>
                    </horizontal>
                </scan>
                <range>
                    <min>0.1</min>
                    <max>8.0</max>
                    <resolution>0.01</resolution>
                </range>
                <noise>
                    <type>gaussian</type>
                    <mean>0.0</mean>
                    <stddev>0.05</stddev>
                </noise>
            </ray>
            <always_on>1</always_on>
            <visualize>true</visualize>
        </sensor>
        </link>

        <joint name="LD14P" type="fixed">
        <parent>base_link</parent>
        <child>LD14P_Link</child>
        </joint>


        <!-- Front Right Wheel Assembly -->
        <link name="Mount_Link_FR">
        <pose relative_to="base_link">0.055873 -0.05 -0.0092866 0 0 0</pose>
        <inertial>
            <pose>-2.8937E-05 0.0057418 0.00032322 0 0 0</pose>
            <mass>0.00088951</mass>
            <inertia>
            <ixx>2.4974E-08</ixx>
            <ixy>-3.6241E-11</ixy>
            <ixz>-9.203E-11</ixz>
            <iyy>6.2294E-08</iyy>
            <iyz>1.983E-09</iyz>
            <izz>5.9248E-08</izz>
            </inertia>
        </inertial>
        <visual name="Mount_Link_FR_visual">
            <pose>0 0 0 0 0 0</pose>
            <geometry>
            <mesh>
                <uri>model://rover/meshes/Mount_Link_FR.STL</uri>
            </mesh>
            </geometry>
            <material>
            <ambient>0.44706 0.47451 0.50196 1</ambient>
            <diffuse>0.44706 0.47451 0.50196 1</diffuse>
            </material>
        </visual>
        <collision name="Mount_Link_FR_collision">
            <pose>0 0 0 0 0 0</pose>
            <geometry>
            <mesh>
                <uri>model://rover/meshes/Mount_Link_FR.STL</uri>
            </mesh>
            </geometry>
        </collision>
        </link>

        <joint name="Mount_FR" type="fixed">
        <parent>base_link</parent>
        <child>Mount_Link_FR</child>
        </joint>

        <link name="Motor_Link_FR">
        <pose relative_to="Mount_Link_FR">7.6341E-05 -0.0092 0.0012869 0 0 0</pose>
        <inertial>
            <pose>-6.0305E-05 0.026341 0.00088289 0 0 0</pose>
            <mass>0.0028388</mass>
            <inertia>
            <ixx>5.2064E-08</ixx>
            <ixy>8.1692E-12</ixy>
            <ixz>-2.1321E-10</ixz>
            <iyy>5.1223E-08</iyy>
            <iyz>9.4713E-12</iyz>
            <izz>5.0388E-08</izz>
            </inertia>
        </inertial>
        <visual name="Motor_Link_FR_visual">
            <pose>0 0 0 0 0 0</pose>
            <geometry>
            <mesh>
                <uri>model://rover/meshes/Motor_Link_FR.STL</uri>
            </mesh>
            </geometry>
            <material>
            <ambient>0.79608 0.79608 0.79608 1</ambient>
            <diffuse>0.79608 0.79608 0.79608 1</diffuse>
            </material>
        </visual>
        <collision name="Motor_Link_FR_collision">
            <pose>0 0 0 0 0 0</pose>
            <geometry>
            <mesh>
                <uri>model://rover/meshes/Motor_Link_FR.STL</uri>
            </mesh>
            </geometry>
        </collision>
        </link>

        <joint name="Motor_FR" type="fixed">
        <parent>Mount_Link_FR</parent>
        <child>Motor_Link_FR</child>
        </joint>

        <link name="Wheel_Link_FR">
        <pose relative_to="Motor_Link_FR">-7.6341E-05 0.0084 0 0 0 0</pose>
        <inertial>
            <pose>5.7778E-11 -0.01821 -4.7703E-11 0 0 0</pose>
            <mass>0.035175</mass>
            <inertia>
            <ixx>1.5237E-05</ixx>
            <ixy>2.2092E-14</ixy>
            <ixz>4.4745E-10</ixz>
            <iyy>2.5786E-05</iyy>
            <iyz>-3.1145E-14</iyz>
            <izz>1.5237E-05</izz>
            </inertia>
        </inertial>
        <visual name="Wheel_Link_FR_visual">
            <pose>0 0 0 0 0 0</pose>
            <geometry>
            <mesh>
                <uri>model://rover/meshes/Wheel_Link_FR.STL</uri>
            </mesh>
            </geometry>
            <material>
            <ambient>0.79216 0.81961 0.93333 1</ambient>
            <diffuse>0.79216 0.81961 0.93333 1</diffuse>
            </material>
        </visual>
        <collision name="Wheel_Link_FR_collision">
            <pose>0 0 0 0 0 0</pose>
            <geometry>
            <mesh>
                <uri>model://rover/meshes/Wheel_Link_FR.STL</uri>
            </mesh>
            </geometry>
        </collision>
        </link>

        <joint name="Wheel_FR" type="revolute">
        <parent>Motor_Link_FR</parent>
        <child>Wheel_Link_FR</child>
        <axis>
            <xyz>0 1 0</xyz>
            <limit>
            <lower>-1.79769e+308</lower>
            <upper>1.79769e+308</upper>
            </limit>
        </axis>
        </joint>

        <!-- Front Left Wheel Assembly -->
        <link name="Mount_Link_FL">
        <pose relative_to="base_link">0.055873 0.05 -0.0092866 0 0 0</pose>
        <inertial>
            <pose>2.89374526260128E-05 -0.00574180489474202 0.000323223503266032 0 0 0</pose>
            <mass>0.000889511101495515</mass>
            <inertia>
            <ixx>2.497444539411E-08</ixx>
            <ixy>-3.6240651239437E-11</ixy>
            <ixz>9.2029843628899E-11</ixz>
            <iyy>6.22940092253975E-08</iyy>
            <iyz>-1.98296057293581E-09</iyz>
            <izz>5.92484943284019E-08</izz>
            </inertia>
        </inertial>
        <visual name="Mount_Link_FL_visual">
            <pose>0 0 0 0 0 0</pose>
            <geometry>
            <mesh>
                <uri>model://rover/meshes/Mount_Link_FL.STL</uri>
            </mesh>
            </geometry>
            <material>
            <ambient>0.447058823529412 0.474509803921569 0.501960784313725 1</ambient>
            <diffuse>0.447058823529412 0.474509803921569 0.501960784313725 1</diffuse>
            </material>
        </visual>
        <collision name="Mount_Link_FL_collision">
            <pose>0 0 0 0 0 0</pose>
            <geometry>
            <mesh>
                <uri>model://rover/meshes/Mount_Link_FL.STL</uri>
            </mesh>
            </geometry>
        </collision>
        </link>

        <joint name="Mount_FL" type="fixed">
        <parent>base_link</parent>
        <child>Mount_Link_FL</child>
        </joint>

        <link name="Motor_Link_FL">
        <pose relative_to="Mount_Link_FL">-7.63405011604268E-05 0.00919999999999997 0.00128688689012445 0 0 0</pose>
        <inertial>
            <pose>6.03046968803145E-05 -0.0263412887088174 0.000882893673382839 0 0 0</pose>
            <mass>0.00283879570267248</mass>
            <inertia>
            <ixx>5.20644968727663E-08</ixx>
            <ixy>8.16932903691748E-12</ixy>
            <ixz>2.13211914887738E-10</ixz>
            <iyy>5.12226271656975E-08</iyy>
            <iyz>-9.4713293078595E-12</iyz>
            <izz>5.03883033851809E-08</izz>
            </inertia>
        </inertial>
        <visual name="Motor_Link_FL_visual">
            <pose>0 0 0 0 0 0</pose>
            <geometry>
            <mesh>
                <uri>model://rover/meshes/Motor_Link_FL.STL</uri>
            </mesh>
            </geometry>
            <material>
            <ambient>0.796078431372549 0.796078431372549 0.796078431372549 1</ambient>
            <diffuse>0.796078431372549 0.796078431372549 0.796078431372549 1</diffuse>
            </material>
        </visual>
        <collision name="Motor_Link_FL_collision">
            <pose>0 0 0 0 0 0</pose>
            <geometry>
            <mesh>
                <uri>model://rover/meshes/Motor_Link_FL.STL</uri>
            </mesh>
            </geometry>
        </collision>
        </link>

        <joint name="Motor_FL" type="fixed">
        <parent>Mount_Link_FL</parent>
        <child>Motor_Link_FL</child>
        </joint>

        <link name="Wheel_Link_FL">
        <pose relative_to="Motor_Link_FL">7.63405011604476E-05 -0.00840000000000002 0 0 0 0</pose>
        <inertial>
            <pose>-7.45820558090138E-11 0.0182100813888 7.17062607208385E-12 0 0 0</pose>
            <mass>0.035174698582227</mass>
            <inertia>
            <ixx>1.52366268256632E-05</ixx>
            <ixy>3.76506163752978E-14</ixy>
            <ixz>-2.1550742782768E-10</ixz>
            <iyy>2.57857822002641E-05</iyy>
            <iyz>6.3766971496481E-15</iyz>
            <izz>1.52375222771183E-05</izz>
            </inertia>
        </inertial>
        <visual name="Wheel_Link_FL_visual">
            <pose>0 0 0 0 0 0</pose>
            <geometry>
            <mesh>
                <uri>model://rover/meshes/Wheel_Link_FL.STL</uri>
            </mesh>
            </geometry>
            <material>
            <ambient>0.792156862745098 0.819607843137255 0.933333333333333 1</ambient>
            <diffuse>0.792156862745098 0.819607843137255 0.933333333333333 1</diffuse>
            </material>
        </visual>
        <collision name="Wheel_Link_FL_collision">
            <pose>0 0 0 0 0 0</pose>
            <geometry>
            <mesh>
                <uri>model://rover/meshes/Wheel_Link_FL.STL</uri>
            </mesh>
            </geometry>
        </collision>
        </link>

        <joint name="Wheel_FL" type="revolute">
        <parent>Motor_Link_FL</parent>
        <child>Wheel_Link_FL</child>
        <axis>
            <xyz>0 1 0</xyz>
            <limit>
            <lower>-1.79769e+308</lower>
            <upper>1.79769e+308</upper>
            </limit>
        </axis>
        </joint>

        <!-- Back Left Wheel Assembly -->
        <link name="Mount_Link_BL">
        <pose relative_to="base_link">-0.056127 0.05 -0.0092866 0 0 0</pose>
        <inertial>
            <pose>2.89374526260197E-05 -0.00574180489474202 0.000323223503266031 0 0 0</pose>
            <mass>0.000889511101495515</mass>
            <inertia>
            <ixx>2.497444539411E-08</ixx>
            <ixy>-3.62406512394373E-11</ixy>
            <ixz>9.20298436289031E-11</ixz>
            <iyy>6.22940092253975E-08</iyy>
            <iyz>-1.98296057293581E-09</iyz>
            <izz>5.92484943284018E-08</izz>
            </inertia>
        </inertial>
        <visual name="Mount_Link_BL_visual">
            <pose>0 0 0 0 0 0</pose>
            <geometry>
            <mesh>
                <uri>model://rover/meshes/Mount_Link_BL.STL</uri>
            </mesh>
            </geometry>
            <material>
            <ambient>0.447058823529412 0.474509803921569 0.501960784313725 1</ambient>
            <diffuse>0.447058823529412 0.474509803921569 0.501960784313725 1</diffuse>
            </material>
        </visual>
        <collision name="Mount_Link_BL_collision">
            <pose>0 0 0 0 0 0</pose>
            <geometry>
            <mesh>
                <uri>model://rover/meshes/Mount_Link_BL.STL</uri>
            </mesh>
            </geometry>
        </collision>
        </link>

        <joint name="Mount_BL" type="fixed">
        <parent>base_link</parent>
        <child>Mount_Link_BL</child>
        </joint>

        <link name="Motor_Link_BL">
        <pose relative_to="Mount_Link_BL">7.63405011606419E-05 0.00919999999999999 0.0012863796207111 0 0 0</pose>
        <inertial>
            <pose>-6.030459023839E-05 -0.0263412887982114 -0.000882893768063883 0 0 0</pose>
            <mass>0.00283879567406719</mass>
            <inertia>
            <ixx>5.20644961834455E-08</ixx>
            <ixy>-8.16930221775181E-12</ixy>
            <ixz>2.13211883274157E-10</ixz>
            <iyy>5.12226271617704E-08</iyy>
            <iyz>9.4712344391227E-12</iyz>
            <izz>5.03883026605782E-08</izz>
            </inertia>
        </inertial>
        <visual name="Motor_Link_BL_visual">
            <pose>0 0 0 0 0 0</pose>
            <geometry>
            <mesh>
                <uri>model://rover/meshes/Motor_Link_BL.STL</uri>
            </mesh>
            </geometry>
            <material>
            <ambient>0.796078431372549 0.796078431372549 0.796078431372549 1</ambient>
            <diffuse>0.796078431372549 0.796078431372549 0.796078431372549 1</diffuse>
            </material>
        </visual>
        <collision name="Motor_Link_BL_collision">
            <pose>0 0 0 0 0 0</pose>
            <geometry>
            <mesh>
                <uri>model://rover/meshes/Motor_Link_BL.STL</uri>
            </mesh>
            </geometry>
        </collision>
        </link>

        <joint name="Motor_BL" type="fixed">
        <parent>Mount_Link_BL</parent>
        <child>Motor_Link_BL</child>
        </joint>

        <link name="Wheel_Link_BL">
        <pose relative_to="Motor_Link_BL">-7.63405011606141E-05 -0.00840000000000001 0 0 0 0</pose>
        <inertial>
            <pose>4.3705178365272E-12 0.0182100813888 7.47986212898399E-11 0 0 0</pose>
            <mass>0.0351746985822267</mass>
            <inertia>
            <ixx>1.52375048767784E-05</ixx>
            <ixy>7.78410523677623E-15</ixy>
            <ixz>2.48438778432416E-10</ixz>
            <iyy>2.57857822002643E-05</iyy>
            <iyz>-3.73823276527771E-14</iyz>
            <izz>1.52366442259736E-05</izz>
            </inertia>
        </inertial>
        <visual name="Wheel_Link_BL_visual">
            <pose>0 0 0 0 0 0</pose>
            <geometry>
            <mesh>
                <uri>model://rover/textures/Wheel_Link_BL.dae</uri>
            </mesh>
            </geometry>
        </visual>
        <collision name="Wheel_Link_BL_collision">
            <pose>0 0 0 0 0 0</pose>
            <geometry>
            <mesh>
                <uri>model://rover/meshes/Wheel_Link_BL.STL</uri>
            </mesh>
            </geometry>
        </collision>
        </link>

        <joint name="Wheel_BL" type="revolute">
        <parent>Motor_Link_BL</parent>
        <child>Wheel_Link_BL</child>
        <axis>
            <xyz>0 1 0</xyz>
            <limit>
            <lower>-1.79769e+308</lower>
            <upper>1.79769e+308</upper>
            </limit>
        </axis>
        </joint>

        <!-- Back Right Wheel Assembly -->
        <link name="Mount_Link_BR">
        <pose relative_to="base_link">-0.0561270249631181 -0.0499999999999994 -0.00928663325541777 0 0 0</pose>
        <inertial>
            <pose>0 0 0 0 0 0</pose>
            <mass>0.001</mass>
            <inertia>
            <ixx>0.000001</ixx>
            <ixy>0</ixy>
            <ixz>0</ixz>
            <iyy>0.000001</iyy>
            <iyz>0</iyz>
            <izz>0.000001</izz>
            </inertia>
        </inertial>
        <visual name="Mount_Link_BR_visual">
            <pose>0 0 0 0 0 0</pose>
            <geometry>
            <mesh>
                <uri>model://rover/meshes/Mount_Link_BR.STL</uri>
            </mesh>
            </geometry>
            <material>
            <ambient>1 1 1 1</ambient>
            <diffuse>1 1 1 1</diffuse>
            </material>
        </visual>
        <collision name="Mount_Link_BR_collision">
            <pose>0 0 0 0 0 0</pose>
            <geometry>
            <mesh>
                <uri>model://rover/meshes/Mount_Link_BR.STL</uri>
            </mesh>
            </geometry>
        </collision>
        </link>

        <joint name="Mount_BR" type="fixed">
        <parent>base_link</parent>
        <child>Mount_Link_BR</child>
        </joint>

        <link name="Motor_Link_BR">
        <pose relative_to="Mount_Link_BR">-7.63405011606072E-05 -0.0092 0.0012863796207111 0 0 0</pose>
        <inertial>
            <pose>6.03046153492687E-05 0.0263412889891294 -0.00088289376174546 0 0 0</pose>
            <mass>0.0028387955894548</mass>
            <inertia>
            <ixx>5.20644945289959E-08</ixx>
            <ixy>-8.16931021094843E-12</ixy>
            <ixz>-2.13211916263588E-10</ixz>
            <iyy>5.122262714054E-08</iyy>
            <iyz>-9.47133094088897E-12</iyz>
            <izz>5.03883010411983E-08</izz>
            </inertia>
        </inertial>
        <visual name="Motor_Link_BR_visual">
            <pose>0 0 0 0 0 0</pose>
            <geometry>
            <mesh>
                <uri>model://rover/meshes/Motor_Link_BR.STL</uri>
            </mesh>
            </geometry>
            <material>
            <ambient>0.796078431372549 0.796078431372549 0.796078431372549 1</ambient>
            <diffuse>0.796078431372549 0.796078431372549 0.796078431372549 1</diffuse>
            </material>
        </visual>
        <collision name="Motor_Link_BR_collision">
            <pose>0 0 0 0 0 0</pose>
            <geometry>
            <mesh>
                <uri>model://rover/meshes/Motor_Link_BR.STL</uri>
            </mesh>
            </geometry>
        </collision>
        </link>

        <joint name="Motor_BR" type="fixed">
        <parent>Mount_Link_BR</parent>
        <child>Motor_Link_BR</child>
        </joint>

        <link name="Wheel_Link_BR">
        <pose relative_to="Motor_Link_BR">7.63405011606072E-05 0.0084 0 0 0 0</pose>
        <inertial>
            <pose>6.12851297487893E-11 -0.0182100813888 4.31050247579057E-11 0 0 0</pose>
            <mass>0.0351746985822271</mass>
            <inertia>
            <ixx>1.52366604616097E-05</ixx>
            <ixy>3.58796086606825E-14</ixy>
            <ixz>-2.74647742451226E-10</ixz>
            <iyy>2.57857822002649E-05</iyy>
            <iyz>1.30708201068383E-14</iyz>
            <izz>1.5237488641291E-05</izz>
            </inertia>
        </inertial>
        <visual name="Wheel_Link_BR_visual">
            <pose>0 0 0 0 0 0</pose>
            <geometry>
            <mesh>
                <uri>model://rover/meshes/Wheel_Link_BR.STL</uri>
            </mesh>
            </geometry>
            <material>
            <ambient>0.792156862745098 0.819607843137255 0.933333333333333 1</ambient>
            <diffuse>0.792156862745098 0.819607843137255 0.933333333333333 1</diffuse>
            </material>
        </visual>
        <collision name="Wheel_Link_BR_collision">
            <pose>0 0 0 0 0 0</pose>
            <geometry>
            <mesh>
                <uri>model://rover/meshes/Wheel_Link_BR.STL</uri>
            </mesh>
            </geometry>
        </collision>
        </link>

        <joint name="Wheel_BR" type="revolute">
        <parent>Motor_Link_BR</parent>
        <child>Wheel_Link_BR</child>
        <axis>
            <xyz>0 1 0</xyz>
            <limit>
            <lower>-1.79769e+308</lower>
            <upper>1.79769e+308</upper>
            </limit>
        </axis>
        </joint>

        <plugin filename="gz-sim-diff-drive-system" name="gz::sim::systems::DiffDrive">
            <left_joint>Wheel_FL</left_joint>
            <left_joint>Wheel_BL</left_joint>
            <right_joint>Wheel_FR</right_joint>
            <right_joint>Wheel_BR</right_joint>
            <wheel_separation>0.138</wheel_separation>
            <wheel_radius>0.0325</wheel_radius>
            <odom_publish_frequency>100</odom_publish_frequency>
            <topic>cmd_vel</topic>
            <odom_topic>odom</odom_topic> 
        </plugin>
    </model>
</sdf>